<?xml version="1.0" encoding="UTF-8"?>
<!-- Generated by org.testng.reporters.JUnitReportReporter -->
<testsuite hostname="DESKTOP-4QRLMTN" failures="0" tests="4" name="com.selenium.TestNg.Testing" time="0.070" errors="1" timestamp="2024-02-02T16:43:51 IST" skipped="0">
  <testcase classname="com.selenium.TestNg.Testing" name="testthree" time="0.030"/>
  <testcase classname="com.selenium.TestNg.Testing" name="testone" time="0.008">
    <error message="
Method Testing.testone()[pri:0, instance:com.selenium.TestNg.Testing@202b0582] should have thrown an exception of type class java.lang.NullPointerException" type="org.testng.TestException">
      <![CDATA[org.testng.TestException: 
Method Testing.testone()[pri:0, instance:com.selenium.TestNg.Testing@202b0582] should have thrown an exception of type class java.lang.NullPointerException
at org.testng.internal.invokers.ExpectedExceptionsHolder.noException(ExpectedExceptionsHolder.java:81)
at org.testng.internal.invokers.TestInvoker.considerExceptions(TestInvoker.java:860)
at org.testng.internal.invokers.TestInvoker.invokeMethod(TestInvoker.java:718)
at org.testng.internal.invokers.TestInvoker.invokeTestMethod(TestInvoker.java:227)
at org.testng.internal.invokers.MethodRunner.runInSequence(MethodRunner.java:50)
at org.testng.internal.invokers.TestInvoker$MethodInvocationAgent.invoke(TestInvoker.java:957)
at org.testng.internal.invokers.TestInvoker.invokeTestMethods(TestInvoker.java:200)
at org.testng.internal.invokers.TestMethodWorker.invokeTestMethods(TestMethodWorker.java:148)
at org.testng.internal.invokers.TestMethodWorker.run(TestMethodWorker.java:128)
at java.base/java.util.ArrayList.forEach(ArrayList.java:1511)
at org.testng.TestRunner.privateRun(TestRunner.java:848)
at org.testng.TestRunner.run(TestRunner.java:621)
at org.testng.SuiteRunner.runTest(SuiteRunner.java:443)
at org.testng.SuiteRunner.runSequentially(SuiteRunner.java:437)
at org.testng.SuiteRunner.privateRun(SuiteRunner.java:397)
at org.testng.SuiteRunner.run(SuiteRunner.java:336)
at org.testng.SuiteRunnerWorker.runSuite(SuiteRunnerWorker.java:52)
at org.testng.SuiteRunnerWorker.run(SuiteRunnerWorker.java:95)
at org.testng.TestNG.runSuitesSequentially(TestNG.java:1280)
at org.testng.TestNG.runSuitesLocally(TestNG.java:1200)
at org.testng.TestNG.runSuites(TestNG.java:1114)
at org.testng.TestNG.run(TestNG.java:1082)
at org.testng.remote.AbstractRemoteTestNG.run(AbstractRemoteTestNG.java:115)
at org.testng.remote.RemoteTestNG.initAndRun(RemoteTestNG.java:251)
at org.testng.remote.RemoteTestNG.main(RemoteTestNG.java:77)
]]>
    </error>
  </testcase> <!-- testone -->
  <testcase classname="com.selenium.TestNg.Testing" name="testtwo" time="0.020"/>
  <testcase classname="com.selenium.TestNg.Testing" name="testfour" time="0.012"/>
</testsuite> <!-- com.selenium.TestNg.Testing -->
